<?xml version="1.0"?>

<robot name="pioneer3dx"
	xmlns:sensor="http://playerstage.sourceforge.net/gazebo/xmlschema/#sensor"
	xmlns:controller="http://playerstage.sourceforge.net/gazebo/xmlschema/#controller"
	xmlns:interface="http://playerstage.sourceforge.net/gazebo/xmlschema/#interface"
	xmlns:xacro="http://ros.org/wiki/xacro">

  <!--<include filename="$(find p2os_urdf)/defs/materials.xacro"/>-->
  <include filename="$(find p2os_urdf)/defs/pioneer3dx_wheel.xacro"/>
  

<!-- Chassis -->
	<link name="base_link">
		<inertial>
			<mass value="3.5"/>
			<!--<origin xyz="-0.025 0 -0.223"/>-->
			<origin xyz="0 0 0"/>
			<inertia ixx="1" ixy="0" ixz="0"
				 iyy="1" iyz="0"
				 izz="1"/>
		</inertial>
		<visual>
			<origin xyz="-0.045 0 0.148" rpy="0 0 0"/>
			<geometry name="pioneer_geom">
				<mesh filename="package://p2os_urdf/meshes/p3dx_meshes/chassis.stl"/>
			</geometry>
			<material name="ChassisRed">
				<color rgba="0.851 0.0 0.0 1.0"/>
			</material>
		</visual>
		<collision>
			<origin xyz="0 0 0" rpy="0 0 0"/>
				<geometry>
					<box size="0.01 0.01 0.01"/>
				</geometry>
		</collision>
	</link>

    <joint name="base_top_joint" type="fixed">
		<origin xyz="-0.045 0 0.234" rpy="0 0 0"/>
		<axis xzy="0 0 1"/>
		<parent link="base_link"/>
		<child link="top_plate"/>
	</joint>
	<link name="base_top">
		<inertial>
			<mass value="0"/>	
			<origin xyz="0 0 0"/>
			<inertia ixx="1" ixy="0" ixz="0"
				 iyy="1" iyz="0"
 				izz="1"/>
		</inertial>
		<visual>
			<origin xyz="0 0 0" rpy="0 0 0"/>
			<geometry name="pioneer_geom">
				<mesh filename="package://p2os_urdf/meshes/p3dx_meshes/top.stl"/>
			</geometry>
			<material name="TopBlack">
					<color rgba="0.038 0.038 0.038 1.0"/>
			</material>
		</visual>
		<collision>
			<origin xyz="0 0 0" rpy="0 0 0"/>
			<geometry>
				<box size="0 0 0"/>
			</geometry>
		</collision>
	</link>


<!-- Swivel -->
	<link name="swivel">
		<inertial>
			<mass value="0.1"/>	
			<origin xyz="0 0 0"/>
			<inertia ixx="0.01" ixy="0" ixz="0"
				 iyy="1" iyz="0" izz="0.01"/>
  	 	</inertial>
	<visual name="base_visual">
		<origin xyz="0 0 0" rpy="0 0 0"/>
		<geometry name="pioneer_geom">
			<mesh filename="package://p2os_urdf/meshes/p3dx_meshes/swivel.stl"/>
		</geometry>
		<material name="swivel">
			<color rgba="0.5 0.5 0.5 1"/>
		</material>
	</visual>
	<collision>
		<origin xyz="0 0 0" rpy="0 0 0"/>
		<geometry>
			<box size="0 0 0"/>
		</geometry>
	</collision>
	</link>

 	<joint name="base_swivel_joint" type="fixed">
		<origin xyz="-0.185 0 0.055" rpy="0 0 0"/>
		<axis xyz="0 0 1" />
		<anchor xyz="0 0 0" />
		<limit effort="100" velocity="100" k_velocity="0" />
		<joint_properties damping="0.0" friction="0.0" />
		<parent link="base_link"/>
		<child link="swivel"/>
	</joint>

<!-- Center Wheel + Hubcap -->
	<link name="center_hubcap">
		<inertial>
			<mass value="0"/>	
			<origin xyz="0 0 0"/>
			<inertia ixx="1" ixy="0" ixz="0"
				 iyy="1" iyz="0" izz="1"/>
  	 	</inertial>
	<visual name="base_visual">
		<origin xyz="0 0 0" rpy="0 0 0"/>
		<geometry name="pioneer_geom">
			<mesh filename="package://p2os_urdf/meshes/p3dx_meshes/center_hubcap.stl"/>
		</geometry>
		<material name="swivel">
			<color rgba="0.5 0.5 0.5 1"/>
		</material>
	</visual>
	<collision>
		<origin xyz="0 0 0" rpy="0 0 0"/>
		<geometry>
			<box size="0 0 0"/>
		</geometry>
	</collision>
	</link>
	
	<joint name="swivel_hubcap_joint" type="continuous">
		<origin xyz="-0.026 0 -0.016" rpy="0 0 0"/>
		<axis xyz="0 1 0" />
		<anchor xyz="0 0 0" />
		<limit effort="100" velocity="100" />
		<joint_properties damping="0.0" friction="0.0" />
		<parent link="swivel"/>
		<child link="center_hubcap"/>
	</joint>

	<link name="center_wheel">
		<inertial>
			<mass value="0"/>	
			<origin xyz="0 0 0"/>
			<inertia ixx="1" ixy="0" ixz="0"
				 iyy="1" iyz="0" izz="1"/>
  	 	</inertial>
	<visual name="base_visual">
		<origin xyz="0 0 0" rpy="0 0 0"/>
		<geometry name="pioneer_geom">
			<mesh filename="package://p2os_urdf/meshes/p3dx_meshes/center_wheel.stl"/>
		</geometry>
		<material name="WheelBlack">
			<color rgba="0.117 0.117 0.117 1"/>
		</material>
	</visual>
	<collision>
		<origin xyz="0 0 0" rpy="0 0 0"/>
		<geometry>
			<box size="0 0 0"/>
		</geometry>
	</collision>
	</link>

	<joint name="center_wheel_joint" type="fixed">
		<origin xyz="-0.0035 0 -0.001" rpy="0 0 0"/>
		<parent link="center_hubcap"/>
		<child link="center_wheel"/>
	</joint>

<xacro:p3dx_wheel suffix="left" reflect="1"/>
<xacro:p3dx_wheel suffix="right" reflect="-1"/>

<!-- Front + Back Sonar -->
	<link name="front_sonar">
		<inertial>
			<mass value="0"/>	
			<origin xyz="0 0 0"/>
			<inertia ixx="1" ixy="0" ixz="0"
				 iyy="1" iyz="0" izz="1"/>
		</inertial>
		<visual name="base_visual">
			<origin xyz="0 0 0" rpy="0 0 0"/>
			<geometry name="pioneer_geom">
				<mesh filename="package://p2os_urdf/meshes/p3dx_meshes/front_sonar.stl"/>
			</geometry>
			<material name="SonarYellow">
				<color rgba="0.715 0.583 0.210 1.0"/>
			</material>
		</visual>
		<collision>
			<origin xyz="0 0 0" rpy="0 0 0"/>
			<geometry>
				<box size="0 0 0"/>
			</geometry>
		</collision>
	</link>

	<joint name="base_front_joint" type="fixed">
		<origin xyz="-0.198 0 0.208" rpy="0 0 0"/>
		<parent link="base_link"/>
		<child link="front_sonar"/>
	</joint>

	<joint name="base_back_joint" type="fixed">
		<origin xyz="0.109 0 0.209" rpy="0 0 0"/>
		<parent link="base_link"/>
		<child link="back_sonar"/>
	</joint>
	<link name="back_sonar">
		<inertial>
			<mass value="0"/>	
			<origin xyz="0 0 0"/>
			<inertia ixx="1" ixy="0" ixz="0"
				 iyy="1" iyz="0" izz="1"/>
		</inertial>
		<visual name="base_visual">
			<origin xyz="0 0 0" rpy="0 0 0"/>
			<geometry name="pioneer_geom">
				<mesh filename="package://p2os_urdf/meshes/p3dx_meshes/back_sonar.stl"/>
			</geometry>
			<material name="SonarYellow">
				<color rgba="0.715 0.583 0.210 1.0"/>
			</material>
		</visual>
		<collision>
			<origin xyz="0 0 0" rpy="0 0 0"/>
			<geometry>
				<box size="0 0 0"/>
			</geometry>
		</collision>
	</link>

	

	<create>
	<back_sonar parent="base_link"/>
  	<top_plate  parent="base_link"/>
  	<swivel     parent="base_link"/>
  	</create>

<gazebo>
	<plugin name="differential_drive_controller" filename="libgazebo_ros_diff_drive.so">
			<alwaysOn>true</alwaysOn>
			<updateRate>100</updateRate>
			<leftJoint>base_right_wheel_joint</leftJoint>
			<rightJoint>base_left_wheel_joint</rightJoint>
			<wheelSeparation>0.39</wheelSeparation>
			<wheelDiameter>0.15</wheelDiameter>
			<torque>5</torque>
			<commandTopic>p3dx/cmd_vel</commandTopic>
			<odometryTopic>p3dx/odom</odometryTopic>
			<odometryFrame>odom</odometryFrame>
			<robotBaseFrame>base_link</robotBaseFrame>
		</plugin>
	</gazebo>
  
	<plugin name="p3d_base_controller" plugin="libgazebo_ros_p3d.so">
		<alwaysOn>true</alwaysOn>
		<updateRate>100.0</updateRate>
		<bodyName>base_link</bodyName>
		<topicName>p3dx/base_pose_ground_truth</topicName>
		<gaussianNoise>0.01</gaussianNoise>
		<frameName>map</frameName>
		<xyzOffsets>0 0 0</xyzOffsets> <!-- initialize odometry for fake localization-->
		<rpyOffsets>0 0 0</rpyOffsets>
	</plugin>

    <!-- this publishes empty joint_states due to no transmission, but
         triggering robot_state_puublisher to publish tf between fixed joints in erratic,
         (e.g. base_laser_link for the base_scan frame) -->
	<plugin name="gazebo_ros_control" filename="libgazebo_ros_control.so">
		<robotNamespace>/p3dx</robotNamespace>
	</plugin>
</gazebo>

</robot>
